2019-11-09 16:06:07 ERROR (MainThread) [homeassistant.components.mqtt] Failed to connect due to exception: [Errno 111] Connection refused
2019-11-09 16:06:12 DEBUG (MainThread) [homeassistant.components.mqtt] Subscribing to owntracks/#
2019-11-09 16:06:12 ERROR (MainThread) [homeassistant.setup] Error handling when_setup callback for mqtt
Traceback (most recent call last):
  File "/srv/homeassistant/lib/python3.5/site-packages/homeassistant/setup.py", line 263, in when_setup
    await when_setup_cb(hass, component)
  File "/srv/homeassistant/lib/python3.5/site-packages/homeassistant/components/owntracks/__init__.py", line 115, in async_connect_mqtt
    context.mqtt_topic, async_handle_mqtt_message, 1)
  File "/srv/homeassistant/lib/python3.5/site-packages/homeassistant/components/mqtt/__init__.py", line 319, in async_subscribe
    qos, encoding)
  File "/srv/homeassistant/lib/python3.5/site-packages/homeassistant/components/mqtt/__init__.py", line 701, in async_subscribe
    await self._async_perform_subscription(topic, qos)
  File "/srv/homeassistant/lib/python3.5/site-packages/homeassistant/components/mqtt/__init__.py", line 736, in _async_perform_subscription
    _raise_on_error(result)
  File "/srv/homeassistant/lib/python3.5/site-packages/homeassistant/components/mqtt/__init__.py", line 821, in _raise_on_error
    'Error talking to MQTT: {}'.format(mqtt.error_string(result_code)))
homeassistant.exceptions.HomeAssistantError: Error talking to MQTT: The client is not currently connected.
2019-11-09 16:06:13 DEBUG (MainThread) [homeassistant.components.mqtt] Subscribing to slave/sensor/mitemp_bt_battery/state
2019-11-09 16:06:13 DEBUG (MainThread) [homeassistant.components.mqtt] Subscribing to slave/sensor/mitemp_bt_temperature/state
2019-11-09 16:06:13 DEBUG (MainThread) [homeassistant.components.mqtt] Subscribing to slave/sensor/mitemp_bt_humidity/state
2019-11-09 16:06:13 ERROR (MainThread) [homeassistant.core] Error doing job: Task exception was never retrieved
Traceback (most recent call last):
  File "/usr/lib/python3.5/asyncio/tasks.py", line 239, in _step
    result = coro.send(None)
  File "/srv/homeassistant/lib/python3.5/site-packages/homeassistant/helpers/entity_platform.py", line 350, in _async_add_entity
    await entity.async_added_to_hass()
  File "/srv/homeassistant/lib/python3.5/site-packages/homeassistant/components/mqtt/sensor.py", line 118, in async_added_to_hass
    await self._subscribe_topics()
  File "/srv/homeassistant/lib/python3.5/site-packages/homeassistant/components/mqtt/sensor.py", line 178, in _subscribe_topics
    'qos': self._config.get(CONF_QOS)}})
  File "/srv/homeassistant/lib/python3.5/site-packages/homeassistant/components/mqtt/subscription.py", line 83, in async_subscribe_topics
    await requested.resubscribe_if_necessary(hass, current)
  File "/srv/homeassistant/lib/python3.5/site-packages/homeassistant/components/mqtt/subscription.py", line 44, in resubscribe_if_necessary
    self.qos, self.encoding
  File "/srv/homeassistant/lib/python3.5/site-packages/homeassistant/components/mqtt/__init__.py", line 319, in async_subscribe
    qos, encoding)
  File "/srv/homeassistant/lib/python3.5/site-packages/homeassistant/components/mqtt/__init__.py", line 701, in async_subscribe
    await self._async_perform_subscription(topic, qos)
  File "/srv/homeassistant/lib/python3.5/site-packages/homeassistant/components/mqtt/__init__.py", line 736, in _async_perform_subscription
    _raise_on_error(result)
  File "/srv/homeassistant/lib/python3.5/site-packages/homeassistant/components/mqtt/__init__.py", line 821, in _raise_on_error
    'Error talking to MQTT: {}'.format(mqtt.error_string(result_code)))
homeassistant.exceptions.HomeAssistantError: Error talking to MQTT: The client is not currently connected.
2019-11-09 16:06:14 ERROR (MainThread) [homeassistant.core] Error doing job: Task exception was never retrieved
Traceback (most recent call last):
  File "/usr/lib/python3.5/asyncio/tasks.py", line 239, in _step
    result = coro.send(None)
  File "/srv/homeassistant/lib/python3.5/site-packages/homeassistant/helpers/entity_platform.py", line 350, in _async_add_entity
    await entity.async_added_to_hass()
  File "/srv/homeassistant/lib/python3.5/site-packages/homeassistant/components/mqtt/sensor.py", line 118, in async_added_to_hass
    await self._subscribe_topics()
  File "/srv/homeassistant/lib/python3.5/site-packages/homeassistant/components/mqtt/sensor.py", line 178, in _subscribe_topics
    'qos': self._config.get(CONF_QOS)}})
  File "/srv/homeassistant/lib/python3.5/site-packages/homeassistant/components/mqtt/subscription.py", line 83, in async_subscribe_topics
    await requested.resubscribe_if_necessary(hass, current)
  File "/srv/homeassistant/lib/python3.5/site-packages/homeassistant/components/mqtt/subscription.py", line 44, in resubscribe_if_necessary
    self.qos, self.encoding
  File "/srv/homeassistant/lib/python3.5/site-packages/homeassistant/components/mqtt/__init__.py", line 319, in async_subscribe
    qos, encoding)
  File "/srv/homeassistant/lib/python3.5/site-packages/homeassistant/components/mqtt/__init__.py", line 701, in async_subscribe
    await self._async_perform_subscription(topic, qos)
  File "/srv/homeassistant/lib/python3.5/site-packages/homeassistant/components/mqtt/__init__.py", line 736, in _async_perform_subscription
    _raise_on_error(result)
  File "/srv/homeassistant/lib/python3.5/site-packages/homeassistant/components/mqtt/__init__.py", line 821, in _raise_on_error
    'Error talking to MQTT: {}'.format(mqtt.error_string(result_code)))
homeassistant.exceptions.HomeAssistantError: Error talking to MQTT: The client is not currently connected.
2019-11-09 16:06:14 ERROR (MainThread) [homeassistant.core] Error doing job: Task exception was never retrieved
Traceback (most recent call last):
  File "/usr/lib/python3.5/asyncio/tasks.py", line 239, in _step
    result = coro.send(None)
  File "/srv/homeassistant/lib/python3.5/site-packages/homeassistant/helpers/entity_platform.py", line 350, in _async_add_entity
    await entity.async_added_to_hass()
  File "/srv/homeassistant/lib/python3.5/site-packages/homeassistant/components/mqtt/sensor.py", line 118, in async_added_to_hass
    await self._subscribe_topics()
  File "/srv/homeassistant/lib/python3.5/site-packages/homeassistant/components/mqtt/sensor.py", line 178, in _subscribe_topics
    'qos': self._config.get(CONF_QOS)}})
  File "/srv/homeassistant/lib/python3.5/site-packages/homeassistant/components/mqtt/subscription.py", line 83, in async_subscribe_topics
    await requested.resubscribe_if_necessary(hass, current)
  File "/srv/homeassistant/lib/python3.5/site-packages/homeassistant/components/mqtt/subscription.py", line 44, in resubscribe_if_necessary
    self.qos, self.encoding
  File "/srv/homeassistant/lib/python3.5/site-packages/homeassistant/components/mqtt/__init__.py", line 319, in async_subscribe
    qos, encoding)
  File "/srv/homeassistant/lib/python3.5/site-packages/homeassistant/components/mqtt/__init__.py", line 701, in async_subscribe
    await self._async_perform_subscription(topic, qos)
  File "/srv/homeassistant/lib/python3.5/site-packages/homeassistant/components/mqtt/__init__.py", line 736, in _async_perform_subscription
    _raise_on_error(result)
  File "/srv/homeassistant/lib/python3.5/site-packages/homeassistant/components/mqtt/__init__.py", line 821, in _raise_on_error
    'Error talking to MQTT: {}'.format(mqtt.error_string(result_code)))
homeassistant.exceptions.HomeAssistantError: Error talking to MQTT: The client is not currently connected.
2019-11-09 16:06:17 ERROR (Thread-15) [homeassistant.components.light.yeelight] Failed to connect to bulb 192.168.0.101, Living Room: A socket error occurred when sending the command.
2019-11-09 16:06:29 WARNING (MainThread) [homeassistant.helpers.entity] Update of sensor.ficus_benjamina_light_intensity is taking over 10 seconds
2019-11-09 16:06:29 WARNING (MainThread) [homeassistant.helpers.entity] Update of sensor.ficus_benjamina_conductivity is taking over 10 seconds
2019-11-09 16:06:29 WARNING (MainThread) [homeassistant.helpers.entity] Update of sensor.ficus_benjamina_temperature is taking over 10 seconds
2019-11-09 16:06:29 WARNING (MainThread) [homeassistant.helpers.entity] Update of sensor.ficus_benjamina_moisture is taking over 10 seconds
2019-11-09 16:06:29 WARNING (MainThread) [homeassistant.helpers.entity] Update of sensor.sukulencik_conductivity is taking over 10 seconds
2019-11-09 16:06:29 WARNING (MainThread) [homeassistant.helpers.entity] Update of sensor.sukulencik_light_intensity is taking over 10 seconds
2019-11-09 16:06:29 WARNING (MainThread) [homeassistant.helpers.entity] Update of sensor.sukulencik_moisture is taking over 10 seconds
2019-11-09 16:06:29 WARNING (MainThread) [homeassistant.helpers.entity] Update of sensor.sukulencik_temperature is taking over 10 seconds
2019-11-09 16:06:29 WARNING (MainThread) [homeassistant.helpers.entity] Update of sensor.calluna_vulgaris_temperature is taking over 10 seconds
2019-11-09 16:06:29 WARNING (MainThread) [homeassistant.helpers.entity] Update of sensor.calluna_vulgaris_light_intensity is taking over 10 seconds
2019-11-09 16:06:29 WARNING (MainThread) [homeassistant.helpers.entity] Update of sensor.calluna_vulgaris_conductivity is taking over 10 seconds
2019-11-09 16:06:29 WARNING (MainThread) [homeassistant.helpers.entity] Update of sensor.calluna_vulgaris_moisture is taking over 10 seconds
2019-11-09 16:06:30 ERROR (Thread-6) [homeassistant.components.sensor.cert_expiry] Connection timeout with server: ufinkowohome.duckdns.org
2019-11-09 16:19:23 ERROR (MainThread) [homeassistant.components.camera.generic] Timeout getting camera image
2019-11-09 17:45:32 ERROR (Recorder) [homeassistant.components.recorder.util] Error executing query: (sqlite3.DatabaseError) database disk image is malformed [SQL: 'INSERT INTO events (event_type, event_data, origin, time_fired, created, context_id, context_user_id) VALUES (?, ?, ?, ?, ?, ?, ?)'] [parameters: ('state_changed', '{"entity_id": "sensor.memory_free", "old_state": {"attributes": {"icon": "mdi:memory", "friendly_name": "Memory free", "unit_of_measurement": "MiB"}, ... (425 characters truncated) ... 17:45:29.037980+00:00", "state": "740.3", "context": {"id": "e8cd2cba408e46bdaf125b8ea65b4938", "user_id": null}, "entity_id": "sensor.memory_free"}}', 'LOCAL', '2019-11-09 17:45:29.038157', '2019-11-09 17:45:32.937521', 'e8cd2cba408e46bdaf125b8ea65b4938', None)] (Background on this error at: http://sqlalche.me/e/4xp6)
2019-11-09 18:06:28 WARNING (MainThread) [homeassistant.helpers.entity] Update of sensor.sukulencik_conductivity is taking over 10 seconds
2019-11-09 18:06:28 WARNING (MainThread) [homeassistant.helpers.entity] Update of sensor.sukulencik_moisture is taking over 10 seconds
2019-11-09 18:06:28 WARNING (MainThread) [homeassistant.helpers.entity] Update of sensor.sukulencik_temperature is taking over 10 seconds
2019-11-09 18:06:28 WARNING (MainThread) [homeassistant.helpers.entity] Update of sensor.sukulencik_light_intensity is taking over 10 seconds
2019-11-09 18:46:30 WARNING (MainThread) [homeassistant.helpers.entity] Update of sensor.calluna_vulgaris_moisture is taking over 10 seconds
2019-11-09 18:46:30 WARNING (MainThread) [homeassistant.helpers.entity] Update of sensor.calluna_vulgaris_temperature is taking over 10 seconds
2019-11-09 18:46:30 WARNING (MainThread) [homeassistant.helpers.entity] Update of sensor.calluna_vulgaris_light_intensity is taking over 10 seconds
2019-11-09 18:46:30 WARNING (MainThread) [homeassistant.helpers.entity] Update of sensor.calluna_vulgaris_conductivity is taking over 10 seconds
2019-11-09 20:49:04 WARNING (MainThread) [homeassistant.helpers.entity] Update of climate.livingroom is taking over 10 seconds
2019-11-09 21:00:12 WARNING (MainThread) [homeassistant.helpers.entity] Update of climate.livingroom is taking over 10 seconds
2019-11-09 21:01:59 ERROR (MainThread) [homeassistant.components.camera.generic] Timeout getting camera image
2019-11-09 21:02:09 ERROR (MainThread) [homeassistant.components.camera.generic] Timeout getting camera image
2019-11-09 21:02:19 ERROR (MainThread) [homeassistant.components.camera.generic] Timeout getting camera image
2019-11-09 21:02:29 ERROR (MainThread) [homeassistant.components.camera.generic] Timeout getting camera image
2019-11-09 21:02:39 ERROR (MainThread) [homeassistant.components.camera.generic] Timeout getting camera image
2019-11-09 21:02:59 ERROR (MainThread) [homeassistant.components.camera.generic] Timeout getting camera image
2019-11-09 21:03:09 ERROR (MainThread) [homeassistant.components.camera.generic] Timeout getting camera image
2019-11-09 21:03:19 ERROR (MainThread) [homeassistant.components.camera.generic] Timeout getting camera image
2019-11-09 21:03:29 ERROR (MainThread) [homeassistant.components.camera.generic] Timeout getting camera image
2019-11-09 21:03:39 ERROR (MainThread) [homeassistant.components.camera.generic] Timeout getting camera image
2019-11-09 21:03:49 ERROR (MainThread) [homeassistant.components.camera.generic] Timeout getting camera image
2019-11-09 21:04:09 ERROR (MainThread) [homeassistant.components.camera.generic] Timeout getting camera image
2019-11-09 21:04:19 ERROR (MainThread) [homeassistant.components.camera.generic] Timeout getting camera image
2019-11-09 21:04:29 ERROR (MainThread) [homeassistant.components.camera.generic] Timeout getting camera image
2019-11-09 21:04:40 ERROR (MainThread) [homeassistant.components.camera.generic] Timeout getting camera image
2019-11-09 21:04:50 ERROR (MainThread) [homeassistant.components.camera.generic] Timeout getting camera image
2019-11-09 21:05:10 ERROR (MainThread) [homeassistant.components.camera.generic] Timeout getting camera image
2019-11-09 21:05:20 WARNING (MainThread) [homeassistant.helpers.entity] Update of climate.bathroom is taking over 10 seconds
2019-11-09 21:05:20 ERROR (MainThread) [homeassistant.components.camera.generic] Timeout getting camera image
2019-11-09 21:05:30 ERROR (MainThread) [homeassistant.components.camera.generic] Timeout getting camera image
2019-11-09 21:05:40 ERROR (MainThread) [homeassistant.components.camera.generic] Timeout getting camera image
2019-11-09 21:05:50 ERROR (MainThread) [homeassistant.components.camera.generic] Timeout getting camera image
2019-11-09 21:06:00 ERROR (MainThread) [homeassistant.components.camera.generic] Timeout getting camera image
2019-11-09 21:06:10 ERROR (MainThread) [homeassistant.components.camera.generic] Timeout getting camera image
2019-11-09 21:06:20 ERROR (MainThread) [homeassistant.components.camera.generic] Timeout getting camera image
2019-11-09 21:06:30 ERROR (MainThread) [homeassistant.components.camera.generic] Timeout getting camera image
2019-11-09 21:06:40 ERROR (MainThread) [homeassistant.components.camera.generic] Timeout getting camera image
2019-11-09 21:06:50 ERROR (MainThread) [homeassistant.components.camera.generic] Timeout getting camera image
2019-11-09 21:07:10 ERROR (MainThread) [homeassistant.components.camera.generic] Timeout getting camera image
2019-11-09 21:07:20 ERROR (MainThread) [homeassistant.components.camera.generic] Timeout getting camera image
2019-11-09 21:07:30 ERROR (MainThread) [homeassistant.components.camera.generic] Timeout getting camera image
2019-11-09 21:07:40 ERROR (MainThread) [homeassistant.components.camera.generic] Timeout getting camera image
2019-11-09 21:07:50 ERROR (MainThread) [homeassistant.components.camera.generic] Timeout getting camera image
